<?xml version="1.0" ?>
<!-- =================================================================================== -->
<!-- |    This document was autogenerated by xacro from aranha_modelo.xacro            | -->
<!-- |    EDITING THIS FILE BY HAND IS NOT RECOMMENDED                                 | -->
<!-- =================================================================================== -->
<robot name="aranha" xmlns:xacro="http://ros.org/wiki/xacro">
  <!--###################### Comunicacao com gazebo ###########################-->
  <gazebo>
    <plugin filename="libgazebo_ros_control.so" name="gazebo_ros_control">
      <robotNamespace>/crab</robotNamespace>
      <!--Nao sei o que faz -->
    </plugin>
  </gazebo>
  <!--######################## Faz a Base do Robo #############################-->
  <link name="base_link"/>
  <joint name="base_joint" type="fixed">
    <parent link="base_link"/>
    <child link="base"/>
    <origin rpy="0 0 0" xyz="0 0 0"/>
  </joint>
  <link name="base">
    <visual>
      <geometry>
        <mesh filename="package://modelo/meshes/base.stl" scale="0.01 0.01 0.01"/>
      </geometry>
      <origin rpy="0 0 1.57079632679" xyz="0 0 0.8"/>
      <material name="verde_limao">
        <color rgba="0.5 0.9 0.5 1"/>
      </material>
    </visual>
    <collision>
      <origin rpy="0.0 0.0 1.57079632679" xyz="0.0  0 0.8"/>
      <geometry>
        <mesh filename="package://modelo/meshes/base.stl" scale="0.01 0.01 0.01"/>
      </geometry>
      <material name="verde_limao">
        <color rgba="0.5 0.9 0.5 1"/>
      </material>
    </collision>
    <inertial>
      <origin rpy="0.0 0.0 0" xyz="0.0  0.0 0"/>
      <mass value="0.00001"/>
      <inertia ixx="1" ixy="0" ixz="0" iyy="1" iyz="0" izz="1"/>
    </inertial>
  </link>
  <gazebo reference="thorax">
    <mu1>0.2</mu1>
    <mu2>0.2</mu2>
    <material>Gazebo/Black</material>
  </gazebo>
  <!--Joint e Link para fixar coxa (caso contrario gira em torno do centro da base)-->
  <joint name="perna_centro_joint_e1" type="fixed">
    <origin rpy="0 0 0" xyz="-0.115 0.65 0.91"/>
    <!-- imp -->
    <parent link="base"/>
    <child link="perna_centro_e1"/>
  </joint>
  <link name="perna_centro_e1">
    <inertial>
      <origin rpy="0.0 0.0 0.0" xyz="0.0 0.0 0.0"/>
      <mass value="0.00001"/>
      <inertia ixx="1" ixy="0" ixz="0" iyy="1" iyz="0" izz="1"/>
    </inertial>
  </link>
  <!--..............Joint entre "base"(thorax) e coxa / Link da Coxa ..........-->
  <joint name="coxa_joint_e1" type="revolute">
    <axis xyz="0 0 1"/>
    <origin rpy="0 0 0" xyz="0 0 0"/>
    <!-- segundo-->
    <parent link="perna_centro_e1"/>
    <child link="coxa_e1"/>
    <limit effort="10000" lower="-1.57079632679" upper="1.57079632679" velocity="100"/>
  </joint>
  <transmission name="coxa_transmission_e1">
    <type>transmission_interface/SimpleTransmission</type>
    <joint name="coxa_joint_e1">
      <hardwareInterface>PositionJointInterface</hardwareInterface>
    </joint>
    <actuator name="coxa_motor_e1">
      <hardwareInterface>PositionJointInterface</hardwareInterface>
      <mechanicalReduction>1</mechanicalReduction>
    </actuator>
  </transmission>
  <link name="coxa_e1">
    <visual>
      <origin rpy="0 0 0" xyz="0 0 0"/>
      <geometry>
        <mesh filename="package://modelo/meshes/coxa_e.stl" scale="0.01 0.01 0.01"/>
      </geometry>
      <material name="">
        <color rgba="0.7 0.7 0 1"/>
      </material>
    </visual>
    <collision>
      <origin rpy="0 0 0" xyz="0 0 0"/>
      <geometry>
        <mesh filename="package://modelo/meshes/coxa_e.stl" scale="0.01 0.01 0.01"/>
      </geometry>
      <material name="">
        <color rgba="0.7 0.7 0 1"/>
      </material>
    </collision>
    <inertial>
      <origin rpy="0.0 0.0 0.0" xyz="0.0 0.0 0.0"/>
      <!--Acho que sao os valores do centro de massa/10-->
      <mass value="0.00001"/>
      <inertia ixx="1" ixy="0" ixz="0" iyy="1" iyz="0" izz="1"/>
    </inertial>
  </link>
  <gazebo reference="coxa_e1">
    <mu1>0.2</mu1>
    <mu2>0.2</mu2>
  </gazebo>
  <!--.................Joint entre coxa e femur / Link ddo Femur. .............-->
  <joint name="femur_joint_e1" type="revolute">
    <origin rpy=" 0 0 0" xyz="-0.52 -0.15 -0.05"/>
    <axis xyz="0 1 0"/>
    <parent link="coxa_e1"/>
    <child link="femur_e1"/>
    <axis xyz="0 0 -1"/>
    <limit effort="10000" lower="-1.57079632679" upper="1.57079632679" velocity="100"/>
  </joint>
  <transmission name="femur_transmission_e1">
    <type>transmission_interface/SimpleTransmission</type>
    <joint name="femur_joint_e1">
      <hardwareInterface>PositionJointInterface</hardwareInterface>
    </joint>
    <actuator name="femur_motor_e1">
      <hardwareInterface>PositionJointInterface</hardwareInterface>
      <mechanicalReduction>1</mechanicalReduction>
    </actuator>
  </transmission>
  <link name="femur_e1">
    <visual>
      <origin rpy="0 0 0" xyz="0 0 0"/>
      <geometry>
        <mesh filename="package://modelo/meshes/femur.stl" scale="0.01 0.01 0.01"/>
      </geometry>
      <material name="">
        <color rgba="0 0.7 0.7 1"/>
      </material>
    </visual>
    <collision>
      <origin rpy="0 0 0" xyz="0 0 0"/>
      <geometry>
        <mesh filename="package://modelo/meshes/femur.stl" scale="0.01 0.01 0.01"/>
      </geometry>
      <material name="">
        <color rgba="0 0.7 0.7 1"/>
      </material>
    </collision>
    <inertial>
      <origin rpy="0.0 0.0 0.0" xyz="0.0 0.0 0.0"/>
      <mass value="0.00001"/>
      <inertia ixx="1" ixy="0" ixz="0" iyy="1" iyz="0" izz="1"/>
    </inertial>
  </link>
  <gazebo reference="femur_e1">
    <mu1>0.2</mu1>
    <mu2>0.2</mu2>
  </gazebo>
  <!--.................Joint entre femur e Tibia / Link do Tibia. .............-->
  <joint name="tibia_joint_e1" type="revolute">
    <origin rpy="0 0 0" xyz="0 0.045 -0.36"/>
    <parent link="femur_e1"/>
    <child link="tibia_e1"/>
    <axis xyz="0 1 0"/>
    <limit effort="10000" lower="-1.57079632679" upper="1.57079632679" velocity="100"/>
  </joint>
  <transmission name="tibia_transmission_e1">
    <type>transmission_interface/SimpleTransmission</type>
    <joint name="tibia_joint_e1">
      <hardwareInterface>PositionJointInterface</hardwareInterface>
    </joint>
    <actuator name="tibia_motor_e1">
      <hardwareInterface>PositionJointInterface</hardwareInterface>
      <mechanicalReduction>1</mechanicalReduction>
    </actuator>
  </transmission>
  <link name="tibia_e1">
    <visual>
      <origin rpy="0 0 0 " xyz="-0 0 0"/>
      <geometry>
        <mesh filename="package://modelo/meshes/tibia.stl" scale="0.01 0.01 0.01"/>
      </geometry>
      <material name="">
        <color rgba="0.7 0 0.7 1"/>
      </material>
    </visual>
    <collision>
      <origin rpy="0 0 0 " xyz="0.0 0.0 0"/>
      <geometry>
        <mesh filename="package://modelo/meshes/tibia.stl" scale="0.01 0.01 0.01"/>
      </geometry>
      <material name="">
        <color rgba="0 0.7 0.7 1"/>
      </material>
    </collision>
    <inertial>
      <origin rpy="0.0 0.0 0.0" xyz="0.0 0.0 0.0"/>
      <mass value="0.00001"/>
      <inertia ixx="1" ixy="0" ixz="0" iyy="1" iyz="0" izz="1"/>
    </inertial>
  </link>
  <!--Joint e Link para fixar coxa (caso contrario gira em torno do centro da base)-->
  <joint name="perna_centro_joint_e2" type="fixed">
    <origin rpy="0 0 0" xyz="-0.115 0 0.91"/>
    <!-- imp -->
    <parent link="base"/>
    <child link="perna_centro_e2"/>
  </joint>
  <link name="perna_centro_e2">
    <inertial>
      <origin rpy="0.0 0.0 0.0" xyz="0.0 0.0 0.0"/>
      <mass value="0.00001"/>
      <inertia ixx="1" ixy="0" ixz="0" iyy="1" iyz="0" izz="1"/>
    </inertial>
  </link>
  <!--..............Joint entre "base"(thorax) e coxa / Link da Coxa ..........-->
  <joint name="coxa_joint_e2" type="revolute">
    <axis xyz="0 0 1"/>
    <origin rpy="0 0 0" xyz="0 0 0"/>
    <!-- segundo-->
    <parent link="perna_centro_e2"/>
    <child link="coxa_e2"/>
    <limit effort="10000" lower="-1.57079632679" upper="1.57079632679" velocity="100"/>
  </joint>
  <transmission name="coxa_transmission_e2">
    <type>transmission_interface/SimpleTransmission</type>
    <joint name="coxa_joint_e2">
      <hardwareInterface>PositionJointInterface</hardwareInterface>
    </joint>
    <actuator name="coxa_motor_e2">
      <hardwareInterface>PositionJointInterface</hardwareInterface>
      <mechanicalReduction>1</mechanicalReduction>
    </actuator>
  </transmission>
  <link name="coxa_e2">
    <visual>
      <origin rpy="0 0 0" xyz="0 0 0"/>
      <geometry>
        <mesh filename="package://modelo/meshes/coxa_e.stl" scale="0.01 0.01 0.01"/>
      </geometry>
      <material name="">
        <color rgba="0.7 0.7 0 1"/>
      </material>
    </visual>
    <collision>
      <origin rpy="0 0 0" xyz="0 0 0"/>
      <geometry>
        <mesh filename="package://modelo/meshes/coxa_e.stl" scale="0.01 0.01 0.01"/>
      </geometry>
      <material name="">
        <color rgba="0.7 0.7 0 1"/>
      </material>
    </collision>
    <inertial>
      <origin rpy="0.0 0.0 0.0" xyz="0.0 0.0 0.0"/>
      <!--Acho que sao os valores do centro de massa/10-->
      <mass value="0.00001"/>
      <inertia ixx="1" ixy="0" ixz="0" iyy="1" iyz="0" izz="1"/>
    </inertial>
  </link>
  <gazebo reference="coxa_e2">
    <mu1>0.2</mu1>
    <mu2>0.2</mu2>
  </gazebo>
  <!--.................Joint entre coxa e femur / Link ddo Femur. .............-->
  <joint name="femur_joint_e2" type="revolute">
    <origin rpy=" 0 0 0" xyz="-0.52 -0.15 -0.05"/>
    <axis xyz="0 1 0"/>
    <parent link="coxa_e2"/>
    <child link="femur_e2"/>
    <axis xyz="0 0 -1"/>
    <limit effort="10000" lower="-1.57079632679" upper="1.57079632679" velocity="100"/>
  </joint>
  <transmission name="femur_transmission_e2">
    <type>transmission_interface/SimpleTransmission</type>
    <joint name="femur_joint_e2">
      <hardwareInterface>PositionJointInterface</hardwareInterface>
    </joint>
    <actuator name="femur_motor_e2">
      <hardwareInterface>PositionJointInterface</hardwareInterface>
      <mechanicalReduction>1</mechanicalReduction>
    </actuator>
  </transmission>
  <link name="femur_e2">
    <visual>
      <origin rpy="0 0 0" xyz="0 0 0"/>
      <geometry>
        <mesh filename="package://modelo/meshes/femur.stl" scale="0.01 0.01 0.01"/>
      </geometry>
      <material name="">
        <color rgba="0 0.7 0.7 1"/>
      </material>
    </visual>
    <collision>
      <origin rpy="0 0 0" xyz="0 0 0"/>
      <geometry>
        <mesh filename="package://modelo/meshes/femur.stl" scale="0.01 0.01 0.01"/>
      </geometry>
      <material name="">
        <color rgba="0 0.7 0.7 1"/>
      </material>
    </collision>
    <inertial>
      <origin rpy="0.0 0.0 0.0" xyz="0.0 0.0 0.0"/>
      <mass value="0.00001"/>
      <inertia ixx="1" ixy="0" ixz="0" iyy="1" iyz="0" izz="1"/>
    </inertial>
  </link>
  <gazebo reference="femur_e2">
    <mu1>0.2</mu1>
    <mu2>0.2</mu2>
  </gazebo>
  <!--.................Joint entre femur e Tibia / Link do Tibia. .............-->
  <joint name="tibia_joint_e2" type="revolute">
    <origin rpy="0 0 0" xyz="0 0.045 -0.36"/>
    <parent link="femur_e2"/>
    <child link="tibia_e2"/>
    <axis xyz="0 1 0"/>
    <limit effort="10000" lower="-1.57079632679" upper="1.57079632679" velocity="100"/>
  </joint>
  <transmission name="tibia_transmission_e2">
    <type>transmission_interface/SimpleTransmission</type>
    <joint name="tibia_joint_e2">
      <hardwareInterface>PositionJointInterface</hardwareInterface>
    </joint>
    <actuator name="tibia_motor_e2">
      <hardwareInterface>PositionJointInterface</hardwareInterface>
      <mechanicalReduction>1</mechanicalReduction>
    </actuator>
  </transmission>
  <link name="tibia_e2">
    <visual>
      <origin rpy="0 0 0 " xyz="-0 0 0"/>
      <geometry>
        <mesh filename="package://modelo/meshes/tibia.stl" scale="0.01 0.01 0.01"/>
      </geometry>
      <material name="">
        <color rgba="0.7 0 0.7 1"/>
      </material>
    </visual>
    <collision>
      <origin rpy="0 0 0 " xyz="0.0 0.0 0"/>
      <geometry>
        <mesh filename="package://modelo/meshes/tibia.stl" scale="0.01 0.01 0.01"/>
      </geometry>
      <material name="">
        <color rgba="0 0.7 0.7 1"/>
      </material>
    </collision>
    <inertial>
      <origin rpy="0.0 0.0 0.0" xyz="0.0 0.0 0.0"/>
      <mass value="0.00001"/>
      <inertia ixx="1" ixy="0" ixz="0" iyy="1" iyz="0" izz="1"/>
    </inertial>
  </link>
  <!--Joint e Link para fixar coxa (caso contrario gira em torno do centro da base)-->
  <joint name="perna_centro_joint_e3" type="fixed">
    <origin rpy="0 0 0" xyz="-0.115 -0.65 0.91"/>
    <!-- imp -->
    <parent link="base"/>
    <child link="perna_centro_e3"/>
  </joint>
  <link name="perna_centro_e3">
    <inertial>
      <origin rpy="0.0 0.0 0.0" xyz="0.0 0.0 0.0"/>
      <mass value="0.00001"/>
      <inertia ixx="1" ixy="0" ixz="0" iyy="1" iyz="0" izz="1"/>
    </inertial>
  </link>
  <!--..............Joint entre "base"(thorax) e coxa / Link da Coxa ..........-->
  <joint name="coxa_joint_e3" type="revolute">
    <axis xyz="0 0 1"/>
    <origin rpy="0 0 0" xyz="0 0 0"/>
    <!-- segundo-->
    <parent link="perna_centro_e3"/>
    <child link="coxa_e3"/>
    <limit effort="10000" lower="-1.57079632679" upper="1.57079632679" velocity="100"/>
  </joint>
  <transmission name="coxa_transmission_e3">
    <type>transmission_interface/SimpleTransmission</type>
    <joint name="coxa_joint_e3">
      <hardwareInterface>PositionJointInterface</hardwareInterface>
    </joint>
    <actuator name="coxa_motor_e3">
      <hardwareInterface>PositionJointInterface</hardwareInterface>
      <mechanicalReduction>1</mechanicalReduction>
    </actuator>
  </transmission>
  <link name="coxa_e3">
    <visual>
      <origin rpy="0 0 0" xyz="0 0 0"/>
      <geometry>
        <mesh filename="package://modelo/meshes/coxa_e.stl" scale="0.01 0.01 0.01"/>
      </geometry>
      <material name="">
        <color rgba="0.7 0.7 0 1"/>
      </material>
    </visual>
    <collision>
      <origin rpy="0 0 0" xyz="0 0 0"/>
      <geometry>
        <mesh filename="package://modelo/meshes/coxa_e.stl" scale="0.01 0.01 0.01"/>
      </geometry>
      <material name="">
        <color rgba="0.7 0.7 0 1"/>
      </material>
    </collision>
    <inertial>
      <origin rpy="0.0 0.0 0.0" xyz="0.0 0.0 0.0"/>
      <!--Acho que sao os valores do centro de massa/10-->
      <mass value="0.00001"/>
      <inertia ixx="1" ixy="0" ixz="0" iyy="1" iyz="0" izz="1"/>
    </inertial>
  </link>
  <gazebo reference="coxa_e3">
    <mu1>0.2</mu1>
    <mu2>0.2</mu2>
  </gazebo>
  <!--.................Joint entre coxa e femur / Link ddo Femur. .............-->
  <joint name="femur_joint_e3" type="revolute">
    <origin rpy=" 0 0 0" xyz="-0.52 -0.15 -0.05"/>
    <axis xyz="0 1 0"/>
    <parent link="coxa_e3"/>
    <child link="femur_e3"/>
    <axis xyz="0 0 -1"/>
    <limit effort="10000" lower="-1.57079632679" upper="1.57079632679" velocity="100"/>
  </joint>
  <transmission name="femur_transmission_e3">
    <type>transmission_interface/SimpleTransmission</type>
    <joint name="femur_joint_e3">
      <hardwareInterface>PositionJointInterface</hardwareInterface>
    </joint>
    <actuator name="femur_motor_e3">
      <hardwareInterface>PositionJointInterface</hardwareInterface>
      <mechanicalReduction>1</mechanicalReduction>
    </actuator>
  </transmission>
  <link name="femur_e3">
    <visual>
      <origin rpy="0 0 0" xyz="0 0 0"/>
      <geometry>
        <mesh filename="package://modelo/meshes/femur.stl" scale="0.01 0.01 0.01"/>
      </geometry>
      <material name="">
        <color rgba="0 0.7 0.7 1"/>
      </material>
    </visual>
    <collision>
      <origin rpy="0 0 0" xyz="0 0 0"/>
      <geometry>
        <mesh filename="package://modelo/meshes/femur.stl" scale="0.01 0.01 0.01"/>
      </geometry>
      <material name="">
        <color rgba="0 0.7 0.7 1"/>
      </material>
    </collision>
    <inertial>
      <origin rpy="0.0 0.0 0.0" xyz="0.0 0.0 0.0"/>
      <mass value="0.00001"/>
      <inertia ixx="1" ixy="0" ixz="0" iyy="1" iyz="0" izz="1"/>
    </inertial>
  </link>
  <gazebo reference="femur_e3">
    <mu1>0.2</mu1>
    <mu2>0.2</mu2>
  </gazebo>
  <!--.................Joint entre femur e Tibia / Link do Tibia. .............-->
  <joint name="tibia_joint_e3" type="revolute">
    <origin rpy="0 0 0" xyz="0 0.045 -0.36"/>
    <parent link="femur_e3"/>
    <child link="tibia_e3"/>
    <axis xyz="0 1 0"/>
    <limit effort="10000" lower="-1.57079632679" upper="1.57079632679" velocity="100"/>
  </joint>
  <transmission name="tibia_transmission_e3">
    <type>transmission_interface/SimpleTransmission</type>
    <joint name="tibia_joint_e3">
      <hardwareInterface>PositionJointInterface</hardwareInterface>
    </joint>
    <actuator name="tibia_motor_e3">
      <hardwareInterface>PositionJointInterface</hardwareInterface>
      <mechanicalReduction>1</mechanicalReduction>
    </actuator>
  </transmission>
  <link name="tibia_e3">
    <visual>
      <origin rpy="0 0 0 " xyz="-0 0 0"/>
      <geometry>
        <mesh filename="package://modelo/meshes/tibia.stl" scale="0.01 0.01 0.01"/>
      </geometry>
      <material name="">
        <color rgba="0.7 0 0.7 1"/>
      </material>
    </visual>
    <collision>
      <origin rpy="0 0 0 " xyz="0.0 0.0 0"/>
      <geometry>
        <mesh filename="package://modelo/meshes/tibia.stl" scale="0.01 0.01 0.01"/>
      </geometry>
      <material name="">
        <color rgba="0 0.7 0.7 1"/>
      </material>
    </collision>
    <inertial>
      <origin rpy="0.0 0.0 0.0" xyz="0.0 0.0 0.0"/>
      <mass value="0.00001"/>
      <inertia ixx="1" ixy="0" ixz="0" iyy="1" iyz="0" izz="1"/>
    </inertial>
  </link>
  <!--Joint e Link para fixar coxa (caso contrario gira em torno do centro da base)-->
  <joint name="perna_centro_joint_d1" type="fixed">
    <origin rpy="0 0 0" xyz="0.115 0 0.91"/>
    <!-- imp -->
    <parent link="base"/>
    <child link="perna_centro_d1"/>
  </joint>
  <link name="perna_centro_d1">
    <inertial>
      <origin rpy="0.0 0.0 0.0" xyz="0.0 0.0 0.0"/>
      <mass value="0.00001"/>
      <inertia ixx="1" ixy="0" ixz="0" iyy="1" iyz="0" izz="1"/>
    </inertial>
  </link>
  <!--..............Joint entre "base"(thorax) e coxa / Link da Coxa ..........-->
  <joint name="coxa_joint_d1" type="revolute">
    <axis xyz="0 0 1"/>
    <origin rpy="0 0 0" xyz="0 0 0"/>
    <!-- segundo-->
    <parent link="perna_centro_d1"/>
    <child link="coxa_d1"/>
    <limit effort="10000" lower="-1.57079632679" upper="1.57079632679" velocity="100"/>
  </joint>
  <transmission name="coxa_transmission_d1">
    <type>transmission_interface/SimpleTransmission</type>
    <joint name="coxa_joint_d1">
      <hardwareInterface>PositionJointInterface</hardwareInterface>
    </joint>
    <actuator name="coxa_motor_d1">
      <hardwareInterface>PositionJointInterface</hardwareInterface>
      <mechanicalReduction>1</mechanicalReduction>
    </actuator>
  </transmission>
  <link name="coxa_d1">
    <visual>
      <origin rpy="0 0 0" xyz="0 0 0"/>
      <geometry>
        <mesh filename="package://modelo/meshes/coxa_d.stl" scale="0.01 0.01 0.01"/>
      </geometry>
      <material name="">
        <color rgba="0.7 0.7 0 1"/>
      </material>
    </visual>
    <collision>
      <origin rpy="0 0 0" xyz="0 0 0"/>
      <geometry>
        <mesh filename="package://modelo/meshes/coxa_d.stl" scale="0.01 0.01 0.01"/>
      </geometry>
      <material name="">
        <color rgba="0.7 0.7 0 1"/>
      </material>
    </collision>
    <inertial>
      <origin rpy="0.0 0.0 0.0" xyz="0.0 0.0 0.0"/>
      <!--Acho que sao os valores do centro de massa/10-->
      <mass value="0.00001"/>
      <inertia ixx="1" ixy="0" ixz="0" iyy="1" iyz="0" izz="1"/>
    </inertial>
  </link>
  <gazebo reference="coxa_d1">
    <mu1>0.2</mu1>
    <mu2>0.2</mu2>
  </gazebo>
  <!--.................Joint entre coxa e femur / Link ddo Femur. .............-->
  <joint name="femur_joint_d1" type="revolute">
    <origin rpy=" 0 0 0" xyz="0.52 -0.15 -0.05"/>
    <axis xyz="0 1 0"/>
    <parent link="coxa_d1"/>
    <child link="femur_d1"/>
    <axis xyz="0 0 -1"/>
    <limit effort="10000" lower="-1.57079632679" upper="1.57079632679" velocity="100"/>
  </joint>
  <transmission name="femur_transmission_d1">
    <type>transmission_interface/SimpleTransmission</type>
    <joint name="femur_joint_d1">
      <hardwareInterface>PositionJointInterface</hardwareInterface>
    </joint>
    <actuator name="femur_motor_d1">
      <hardwareInterface>PositionJointInterface</hardwareInterface>
      <mechanicalReduction>1</mechanicalReduction>
    </actuator>
  </transmission>
  <link name="femur_d1">
    <visual>
      <origin rpy="0 0 0" xyz="0 0 0"/>
      <geometry>
        <mesh filename="package://modelo/meshes/femur.stl" scale="0.01 0.01 0.01"/>
      </geometry>
      <material name="">
        <color rgba="0 0.7 0.7 1"/>
      </material>
    </visual>
    <collision>
      <origin rpy="0 0 0" xyz="0 0 0"/>
      <geometry>
        <mesh filename="package://modelo/meshes/femur.stl" scale="0.01 0.01 0.01"/>
      </geometry>
      <material name="">
        <color rgba="0 0.7 0.7 1"/>
      </material>
    </collision>
    <inertial>
      <origin rpy="0.0 0.0 0.0" xyz="0.0 0.0 0.0"/>
      <mass value="0.00001"/>
      <inertia ixx="1" ixy="0" ixz="0" iyy="1" iyz="0" izz="1"/>
    </inertial>
  </link>
  <gazebo reference="femur_d1">
    <mu1>0.2</mu1>
    <mu2>0.2</mu2>
  </gazebo>
  <!--.................Joint entre femur e Tibia / Link do Tibia. .............-->
  <joint name="tibia_joint_d1" type="revolute">
    <origin rpy="0 0 0" xyz="0 0.045 -0.36"/>
    <parent link="femur_d1"/>
    <child link="tibia_d1"/>
    <axis xyz="0 1 0"/>
    <limit effort="10000" lower="-1.57079632679" upper="1.57079632679" velocity="100"/>
  </joint>
  <transmission name="tibia_transmission_d1">
    <type>transmission_interface/SimpleTransmission</type>
    <joint name="tibia_joint_d1">
      <hardwareInterface>PositionJointInterface</hardwareInterface>
    </joint>
    <actuator name="tibia_motor_d1">
      <hardwareInterface>PositionJointInterface</hardwareInterface>
      <mechanicalReduction>1</mechanicalReduction>
    </actuator>
  </transmission>
  <link name="tibia_d1">
    <visual>
      <origin rpy="0 0 0 " xyz="-0 0 0"/>
      <geometry>
        <mesh filename="package://modelo/meshes/tibia.stl" scale="0.01 0.01 0.01"/>
      </geometry>
      <material name="">
        <color rgba="0.7 0 0.7 1"/>
      </material>
    </visual>
    <collision>
      <origin rpy="0 0 0 " xyz="0.0 0.0 0"/>
      <geometry>
        <mesh filename="package://modelo/meshes/tibia.stl" scale="0.01 0.01 0.01"/>
      </geometry>
      <material name="">
        <color rgba="0 0.7 0.7 1"/>
      </material>
    </collision>
    <inertial>
      <origin rpy="0.0 0.0 0.0" xyz="0.0 0.0 0.0"/>
      <mass value="0.00001"/>
      <inertia ixx="1" ixy="0" ixz="0" iyy="1" iyz="0" izz="1"/>
    </inertial>
  </link>
  <!--Joint e Link para fixar coxa (caso contrario gira em torno do centro da base)-->
  <joint name="perna_centro_joint_d2" type="fixed">
    <origin rpy="0 0 0" xyz="0.115 0.65 0.91"/>
    <!-- imp -->
    <parent link="base"/>
    <child link="perna_centro_d2"/>
  </joint>
  <link name="perna_centro_d2">
    <inertial>
      <origin rpy="0.0 0.0 0.0" xyz="0.0 0.0 0.0"/>
      <mass value="0.00001"/>
      <inertia ixx="1" ixy="0" ixz="0" iyy="1" iyz="0" izz="1"/>
    </inertial>
  </link>
  <!--..............Joint entre "base"(thorax) e coxa / Link da Coxa ..........-->
  <joint name="coxa_joint_d2" type="revolute">
    <axis xyz="0 0 1"/>
    <origin rpy="0 0 0" xyz="0 0 0"/>
    <!-- segundo-->
    <parent link="perna_centro_d2"/>
    <child link="coxa_d2"/>
    <limit effort="10000" lower="-1.57079632679" upper="1.57079632679" velocity="100"/>
  </joint>
  <transmission name="coxa_transmission_d2">
    <type>transmission_interface/SimpleTransmission</type>
    <joint name="coxa_joint_d2">
      <hardwareInterface>PositionJointInterface</hardwareInterface>
    </joint>
    <actuator name="coxa_motor_d2">
      <hardwareInterface>PositionJointInterface</hardwareInterface>
      <mechanicalReduction>1</mechanicalReduction>
    </actuator>
  </transmission>
  <link name="coxa_d2">
    <visual>
      <origin rpy="0 0 0" xyz="0 0 0"/>
      <geometry>
        <mesh filename="package://modelo/meshes/coxa_d.stl" scale="0.01 0.01 0.01"/>
      </geometry>
      <material name="">
        <color rgba="0.7 0.7 0 1"/>
      </material>
    </visual>
    <collision>
      <origin rpy="0 0 0" xyz="0 0 0"/>
      <geometry>
        <mesh filename="package://modelo/meshes/coxa_d.stl" scale="0.01 0.01 0.01"/>
      </geometry>
      <material name="">
        <color rgba="0.7 0.7 0 1"/>
      </material>
    </collision>
    <inertial>
      <origin rpy="0.0 0.0 0.0" xyz="0.0 0.0 0.0"/>
      <!--Acho que sao os valores do centro de massa/10-->
      <mass value="0.00001"/>
      <inertia ixx="1" ixy="0" ixz="0" iyy="1" iyz="0" izz="1"/>
    </inertial>
  </link>
  <gazebo reference="coxa_d2">
    <mu1>0.2</mu1>
    <mu2>0.2</mu2>
  </gazebo>
  <!--.................Joint entre coxa e femur / Link ddo Femur. .............-->
  <joint name="femur_joint_d2" type="revolute">
    <origin rpy=" 0 0 0" xyz="0.52 -0.15 -0.05"/>
    <axis xyz="0 1 0"/>
    <parent link="coxa_d2"/>
    <child link="femur_d2"/>
    <axis xyz="0 0 -1"/>
    <limit effort="10000" lower="-1.57079632679" upper="1.57079632679" velocity="100"/>
  </joint>
  <transmission name="femur_transmission_d2">
    <type>transmission_interface/SimpleTransmission</type>
    <joint name="femur_joint_d2">
      <hardwareInterface>PositionJointInterface</hardwareInterface>
    </joint>
    <actuator name="femur_motor_d2">
      <hardwareInterface>PositionJointInterface</hardwareInterface>
      <mechanicalReduction>1</mechanicalReduction>
    </actuator>
  </transmission>
  <link name="femur_d2">
    <visual>
      <origin rpy="0 0 0" xyz="0 0 0"/>
      <geometry>
        <mesh filename="package://modelo/meshes/femur.stl" scale="0.01 0.01 0.01"/>
      </geometry>
      <material name="">
        <color rgba="0 0.7 0.7 1"/>
      </material>
    </visual>
    <collision>
      <origin rpy="0 0 0" xyz="0 0 0"/>
      <geometry>
        <mesh filename="package://modelo/meshes/femur.stl" scale="0.01 0.01 0.01"/>
      </geometry>
      <material name="">
        <color rgba="0 0.7 0.7 1"/>
      </material>
    </collision>
    <inertial>
      <origin rpy="0.0 0.0 0.0" xyz="0.0 0.0 0.0"/>
      <mass value="0.00001"/>
      <inertia ixx="1" ixy="0" ixz="0" iyy="1" iyz="0" izz="1"/>
    </inertial>
  </link>
  <gazebo reference="femur_d2">
    <mu1>0.2</mu1>
    <mu2>0.2</mu2>
  </gazebo>
  <!--.................Joint entre femur e Tibia / Link do Tibia. .............-->
  <joint name="tibia_joint_d2" type="revolute">
    <origin rpy="0 0 0" xyz="0 0.045 -0.36"/>
    <parent link="femur_d2"/>
    <child link="tibia_d2"/>
    <axis xyz="0 1 0"/>
    <limit effort="10000" lower="-1.57079632679" upper="1.57079632679" velocity="100"/>
  </joint>
  <transmission name="tibia_transmission_d2">
    <type>transmission_interface/SimpleTransmission</type>
    <joint name="tibia_joint_d2">
      <hardwareInterface>PositionJointInterface</hardwareInterface>
    </joint>
    <actuator name="tibia_motor_d2">
      <hardwareInterface>PositionJointInterface</hardwareInterface>
      <mechanicalReduction>1</mechanicalReduction>
    </actuator>
  </transmission>
  <link name="tibia_d2">
    <visual>
      <origin rpy="0 0 0 " xyz="-0 0 0"/>
      <geometry>
        <mesh filename="package://modelo/meshes/tibia.stl" scale="0.01 0.01 0.01"/>
      </geometry>
      <material name="">
        <color rgba="0.7 0 0.7 1"/>
      </material>
    </visual>
    <collision>
      <origin rpy="0 0 0 " xyz="0.0 0.0 0"/>
      <geometry>
        <mesh filename="package://modelo/meshes/tibia.stl" scale="0.01 0.01 0.01"/>
      </geometry>
      <material name="">
        <color rgba="0 0.7 0.7 1"/>
      </material>
    </collision>
    <inertial>
      <origin rpy="0.0 0.0 0.0" xyz="0.0 0.0 0.0"/>
      <mass value="0.00001"/>
      <inertia ixx="1" ixy="0" ixz="0" iyy="1" iyz="0" izz="1"/>
    </inertial>
  </link>
  <!--Joint e Link para fixar coxa (caso contrario gira em torno do centro da base)-->
  <joint name="perna_centro_joint_d3" type="fixed">
    <origin rpy="0 0 0" xyz="0.115 -0.65 0.91"/>
    <!-- imp -->
    <parent link="base"/>
    <child link="perna_centro_d3"/>
  </joint>
  <link name="perna_centro_d3">
    <inertial>
      <origin rpy="0.0 0.0 0.0" xyz="0.0 0.0 0.0"/>
      <mass value="0.00001"/>
      <inertia ixx="1" ixy="0" ixz="0" iyy="1" iyz="0" izz="1"/>
    </inertial>
  </link>
  <!--..............Joint entre "base"(thorax) e coxa / Link da Coxa ..........-->
  <joint name="coxa_joint_d3" type="revolute">
    <axis xyz="0 0 1"/>
    <origin rpy="0 0 0" xyz="0 0 0"/>
    <!-- segundo-->
    <parent link="perna_centro_d3"/>
    <child link="coxa_d3"/>
    <limit effort="10000" lower="-1.57079632679" upper="1.57079632679" velocity="100"/>
  </joint>
  <transmission name="coxa_transmission_d3">
    <type>transmission_interface/SimpleTransmission</type>
    <joint name="coxa_joint_d3">
      <hardwareInterface>PositionJointInterface</hardwareInterface>
    </joint>
    <actuator name="coxa_motor_d3">
      <hardwareInterface>PositionJointInterface</hardwareInterface>
      <mechanicalReduction>1</mechanicalReduction>
    </actuator>
  </transmission>
  <link name="coxa_d3">
    <visual>
      <origin rpy="0 0 0" xyz="0 0 0"/>
      <geometry>
        <mesh filename="package://modelo/meshes/coxa_d.stl" scale="0.01 0.01 0.01"/>
      </geometry>
      <material name="">
        <color rgba="0.7 0.7 0 1"/>
      </material>
    </visual>
    <collision>
      <origin rpy="0 0 0" xyz="0 0 0"/>
      <geometry>
        <mesh filename="package://modelo/meshes/coxa_d.stl" scale="0.01 0.01 0.01"/>
      </geometry>
      <material name="">
        <color rgba="0.7 0.7 0 1"/>
      </material>
    </collision>
    <inertial>
      <origin rpy="0.0 0.0 0.0" xyz="0.0 0.0 0.0"/>
      <!--Acho que sao os valores do centro de massa/10-->
      <mass value="0.00001"/>
      <inertia ixx="1" ixy="0" ixz="0" iyy="1" iyz="0" izz="1"/>
    </inertial>
  </link>
  <gazebo reference="coxa_d3">
    <mu1>0.2</mu1>
    <mu2>0.2</mu2>
  </gazebo>
  <!--.................Joint entre coxa e femur / Link ddo Femur. .............-->
  <joint name="femur_joint_d3" type="revolute">
    <origin rpy=" 0 0 0" xyz="0.52 -0.15 -0.05"/>
    <axis xyz="0 1 0"/>
    <parent link="coxa_d3"/>
    <child link="femur_d3"/>
    <axis xyz="0 0 -1"/>
    <limit effort="10000" lower="-1.57079632679" upper="1.57079632679" velocity="100"/>
  </joint>
  <transmission name="femur_transmission_d3">
    <type>transmission_interface/SimpleTransmission</type>
    <joint name="femur_joint_d3">
      <hardwareInterface>PositionJointInterface</hardwareInterface>
    </joint>
    <actuator name="femur_motor_d3">
      <hardwareInterface>PositionJointInterface</hardwareInterface>
      <mechanicalReduction>1</mechanicalReduction>
    </actuator>
  </transmission>
  <link name="femur_d3">
    <visual>
      <origin rpy="0 0 0" xyz="0 0 0"/>
      <geometry>
        <mesh filename="package://modelo/meshes/femur.stl" scale="0.01 0.01 0.01"/>
      </geometry>
      <material name="">
        <color rgba="0 0.7 0.7 1"/>
      </material>
    </visual>
    <collision>
      <origin rpy="0 0 0" xyz="0 0 0"/>
      <geometry>
        <mesh filename="package://modelo/meshes/femur.stl" scale="0.01 0.01 0.01"/>
      </geometry>
      <material name="">
        <color rgba="0 0.7 0.7 1"/>
      </material>
    </collision>
    <inertial>
      <origin rpy="0.0 0.0 0.0" xyz="0.0 0.0 0.0"/>
      <mass value="0.00001"/>
      <inertia ixx="1" ixy="0" ixz="0" iyy="1" iyz="0" izz="1"/>
    </inertial>
  </link>
  <gazebo reference="femur_d3">
    <mu1>0.2</mu1>
    <mu2>0.2</mu2>
  </gazebo>
  <!--.................Joint entre femur e Tibia / Link do Tibia. .............-->
  <joint name="tibia_joint_d3" type="revolute">
    <origin rpy="0 0 0" xyz="0 0.045 -0.36"/>
    <parent link="femur_d3"/>
    <child link="tibia_d3"/>
    <axis xyz="0 1 0"/>
    <limit effort="10000" lower="-1.57079632679" upper="1.57079632679" velocity="100"/>
  </joint>
  <transmission name="tibia_transmission_d3">
    <type>transmission_interface/SimpleTransmission</type>
    <joint name="tibia_joint_d3">
      <hardwareInterface>PositionJointInterface</hardwareInterface>
    </joint>
    <actuator name="tibia_motor_d3">
      <hardwareInterface>PositionJointInterface</hardwareInterface>
      <mechanicalReduction>1</mechanicalReduction>
    </actuator>
  </transmission>
  <link name="tibia_d3">
    <visual>
      <origin rpy="0 0 0 " xyz="-0 0 0"/>
      <geometry>
        <mesh filename="package://modelo/meshes/tibia.stl" scale="0.01 0.01 0.01"/>
      </geometry>
      <material name="">
        <color rgba="0.7 0 0.7 1"/>
      </material>
    </visual>
    <collision>
      <origin rpy="0 0 0 " xyz="0.0 0.0 0"/>
      <geometry>
        <mesh filename="package://modelo/meshes/tibia.stl" scale="0.01 0.01 0.01"/>
      </geometry>
      <material name="">
        <color rgba="0 0.7 0.7 1"/>
      </material>
    </collision>
    <inertial>
      <origin rpy="0.0 0.0 0.0" xyz="0.0 0.0 0.0"/>
      <mass value="0.00001"/>
      <inertia ixx="1" ixy="0" ixz="0" iyy="1" iyz="0" izz="1"/>
    </inertial>
  </link>
</robot>
