<?xml version="1.0" ?>
<!-- =================================================================================== -->
<!-- |    This document was autogenerated by xacro from aranha_modelo.xacro            | -->
<!-- |    EDITING THIS FILE BY HAND IS NOT RECOMMENDED                                 | -->
<!-- =================================================================================== -->
<robot name="aranha" xmlns:xacro="http://ros.org/wiki/xacro">
  <!--###################### Comunicacao com gazebo ###########################-->
  <gazebo>
    <plugin filename="libgazebo_ros_control.so" name="gazebo_ros_control">
      <robotNamespace>/crab</robotNamespace>
      <!--Nao sei o que faz -->
    </plugin>
  </gazebo>
  <!--######################## Faz a Base do Robo #############################-->
  <link name="base_link"/>
  <joint name="base_joint" type="fixed">
    <axis xyz="0 0 1"/>
    <parent link="base_link"/>
    <child link="thorax"/>
    <!-- <origin rpy="0 0 ${pi/2}" xyz="0 0 ${altura_base}"/> -->
    <origin rpy="0 0 0" xyz="0 0 0"/>
  </joint>
  <link name="thorax">
    <visual>
      <geometry>
        <mesh filename="package://robot_description/meshes/base.stl" scale="0.01 0.01 0.01"/>
      </geometry>
      <origin rpy="0 0 1.57079632679" xyz="0 0 0.8"/>
      <material name="verde_limao">
        <color rgba="0.5 0.9 0.5 1"/>
      </material>
    </visual>
  </link>
  <!--Joint e Link para fixar coxa (caso contrario gira em torno do centro da base)-->
  <joint name="perna_centro_joint_1" type="fixed">
    <axis xyz="0 0 1"/>
    <origin rpy="0 0 0" xyz="-0.115 0.65 0.91"/>
    <!-- imp -->
    <parent link="thorax"/>
    <child link="perna_centro_1"/>
  </joint>
  <link name="perna_centro_1">
    <inertial>
      <origin rpy="0.0 0.0 0.0" xyz="0.0 0.0 0.0"/>
      <mass value="0.00001"/>
      <inertia ixx="1" ixy="0" ixz="0" iyy="1" iyz="0" izz="1"/>
    </inertial>
  </link>
  <!--..............Joint entre "thorax"(thorax) e coxa / Link da Coxa ..........-->
  <joint name="coxa_joint_1" type="revolute">
    <parent link="perna_centro_1"/>
    <axis xyz="0 0 1"/>
    <origin rpy="0 0 0" xyz="0 0 0"/>
    <!-- segundo-->
    <child link="coxa_1"/>
    <limit effort="10000" lower="-1.57079632679" upper="1.57079632679" velocity="100"/>
  </joint>
  <transmission name="coxa_transmission_1">
    <type>transmission_interface/SimpleTransmission</type>
    <joint name="coxa_joint_1">
      <hardwareInterface>EffortJointInterface</hardwareInterface>
    </joint>
    <actuator name="coxa_motor_1">
      <hardwareInterface>EffortJointInterface</hardwareInterface>
      <mechanicalReduction>1</mechanicalReduction>
    </actuator>
  </transmission>
  <link name="coxa_1">
    <visual>
      <origin rpy="0 0 0" xyz="0 0 0"/>
      <geometry>
        <mesh filename="package://robot_description/meshes/coxa_e.stl" scale="0.01 0.01 0.01"/>
      </geometry>
      <material name="">
        <color rgba="0.7 0.7 0 1"/>
      </material>
    </visual>
    <collision>
      <origin rpy="0 0 0" xyz="0 0 0"/>
      <geometry>
        <mesh filename="package://robot_description/meshes/coxa_e.stl" scale="0.01 0.01 0.01"/>
      </geometry>
      <material name="">
        <color rgba="0.7 0.7 0 1"/>
      </material>
    </collision>
    <inertial>
      <origin rpy="0.0 0.0 0.0" xyz="0.0 0.0 0.0"/>
      <!--Acho que sao os valores do centro de massa/10-->
      <mass value="0.00001"/>
      <inertia ixx="1" ixy="0" ixz="0" iyy="1" iyz="0" izz="1"/>
    </inertial>
  </link>
  <gazebo reference="coxa_1">
    <mu1>0.2</mu1>
    <mu2>0.2</mu2>
  </gazebo>
  <!--.................Joint entre coxa e femur / Link ddo
    Femur. .............-->
  <joint name="femur_centro_1" type="fixed">
    <axis xyz="0 1 0"/>
    <origin rpy=" 0 0 0" xyz="-0.52 -0.15 -0.05"/>
    <parent link="coxa_1"/>
    <child link="femur_centro_1"/>
  </joint>
  <link name="femur_centro_1">
    <inertial>
      <origin rpy="0.0 0.0 0.0" xyz="0.0 0.0 0.0"/>
      <mass value="0.00001"/>
      <inertia ixx="1" ixy="0" ixz="0" iyy="1" iyz="0" izz="1"/>
    </inertial>
  </link>
  <joint name="femur_joint_1" type="revolute">
    <origin rpy="0 0 0" xyz="0 0 0"/>
    <parent link="femur_centro_1"/>
    <child link="femur_1"/>
    <axis xyz="0 1 0"/>
    <limit effort="10000" lower="-1.57079632679" upper="1.57079632679" velocity="100"/>
  </joint>
  <transmission name="femur_transmission_1">
    <type>transmission_interface/SimpleTransmission</type>
    <joint name="femur_joint_1">
      <hardwareInterface>EffortJointInterface</hardwareInterface>
    </joint>
    <actuator name="femur_motor_1">
      <hardwareInterface>EffortJointInterface</hardwareInterface>
      <mechanicalReduction>1</mechanicalReduction>
    </actuator>
  </transmission>
  <link name="femur_1">
    <visual>
      <origin rpy="0 0 0" xyz="0 0 0"/>
      <geometry>
        <mesh filename="package://robot_description/meshes/femur.stl" scale="0.01 0.01 0.01"/>
      </geometry>
      <material name="">
        <color rgba="0 0.7 0.7 1"/>
      </material>
    </visual>
    <collision>
      <origin rpy="0 0 0" xyz="0 0 0"/>
      <geometry>
        <mesh filename="package://robot_description/meshes/femur.stl" scale="0.01 0.01 0.01"/>
      </geometry>
      <material name="">
        <color rgba="0 0.7 0.7 1"/>
      </material>
    </collision>
    <inertial>
      <origin rpy="0.0 0.0 0.0" xyz="0.0 0.0 0.0"/>
      <mass value="0.00001"/>
      <inertia ixx="1" ixy="0" ixz="0" iyy="1" iyz="0" izz="1"/>
    </inertial>
  </link>
  <gazebo reference="femur_1">
    <mu1>0.2</mu1>
    <mu2>0.2</mu2>
  </gazebo>
  <!--.................Joint entre femur e Tibia / Link do Tibia. .............-->
  <!--Joint e Link para fixar coxa (caso contrario gira em torno do centro da base)-->
  <joint name="tibia_centro_1" type="fixed">
    <axis xyz="0 1 0"/>
    <origin rpy="0 0 0" xyz="0 0.045 -0.36"/>
    <parent link="femur_1"/>
    <child link="tibia_centro_1"/>
  </joint>
  <link name="tibia_centro_1">
    <inertial>
      <origin rpy="0.0 0.0 0.0" xyz="0.0 0.0 0.0"/>
      <mass value="0.00001"/>
      <inertia ixx="1" ixy="0" ixz="0" iyy="1" iyz="0" izz="1"/>
    </inertial>
  </link>
  <joint name="tibia_joint_1" type="revolute">
    <origin rpy="0 0 0" xyz="0 0 0"/>
    <parent link="tibia_centro_1"/>
    <child link="tibia_1"/>
    <axis xyz="0 1 0"/>
    <limit effort="10000" lower="-1.57079632679" upper="1.57079632679" velocity="100"/>
  </joint>
  <transmission name="tibia_transmission_1">
    <type>transmission_interface/SimpleTransmission</type>
    <joint name="tibia_joint_1">
      <hardwareInterface>EffortJointInterface</hardwareInterface>
    </joint>
    <actuator name="tibia_motor_1">
      <hardwareInterface>EffortJointInterface</hardwareInterface>
      <mechanicalReduction>1</mechanicalReduction>
    </actuator>
  </transmission>
  <link name="tibia_1">
    <visual>
      <origin rpy="0 0 0 " xyz="-0 0 0"/>
      <geometry>
        <mesh filename="package://robot_description/meshes/tibia.stl" scale="0.01 0.01 0.01"/>
      </geometry>
      <material name="">
        <color rgba="0.7 0 0.7 1"/>
      </material>
    </visual>
    <collision>
      <origin rpy="0 0 0 " xyz="0.0 0.0 0"/>
      <geometry>
        <mesh filename="package://robot_description/meshes/tibia.stl" scale="0.01 0.01 0.01"/>
      </geometry>
      <material name="">
        <color rgba="0 0.7 0.7 1"/>
      </material>
    </collision>
    <inertial>
      <origin rpy="0.0 0.0 0.0" xyz="0.0 0.0 0.0"/>
      <mass value="0.00001"/>
      <inertia ixx="1" ixy="0" ixz="0" iyy="1" iyz="0" izz="1"/>
    </inertial>
  </link>
  

!--............................. Patas......................................--&gt;

  <joint name="tibia_foot_joint_1" type="fixed">
    <axis xyz="0 0 1"/>
    <origin rpy="0 0 0" xyz="0 0.08 -0.57"/>
    <parent link="tibia_1"/>
    <child link="tibia_foot_1"/>
  </joint>
  <link name="tibia_foot_1">
</link>
  <!--Joint e Link para fixar coxa (caso contrario gira em torno do centro da base)-->
  <joint name="perna_centro_joint_2" type="fixed">
    <axis xyz="0 0 1"/>
    <origin rpy="0 0 0" xyz="-0.115 0 0.91"/>
    <!-- imp -->
    <parent link="thorax"/>
    <child link="perna_centro_2"/>
  </joint>
  <link name="perna_centro_2">
    <inertial>
      <origin rpy="0.0 0.0 0.0" xyz="0.0 0.0 0.0"/>
      <mass value="0.00001"/>
      <inertia ixx="1" ixy="0" ixz="0" iyy="1" iyz="0" izz="1"/>
    </inertial>
  </link>
  <!--..............Joint entre "thorax"(thorax) e coxa / Link da Coxa ..........-->
  <joint name="coxa_joint_2" type="revolute">
    <parent link="perna_centro_2"/>
    <axis xyz="0 0 1"/>
    <origin rpy="0 0 0" xyz="0 0 0"/>
    <!-- segundo-->
    <child link="coxa_2"/>
    <limit effort="10000" lower="-1.57079632679" upper="1.57079632679" velocity="100"/>
  </joint>
  <transmission name="coxa_transmission_2">
    <type>transmission_interface/SimpleTransmission</type>
    <joint name="coxa_joint_2">
      <hardwareInterface>EffortJointInterface</hardwareInterface>
    </joint>
    <actuator name="coxa_motor_2">
      <hardwareInterface>EffortJointInterface</hardwareInterface>
      <mechanicalReduction>1</mechanicalReduction>
    </actuator>
  </transmission>
  <link name="coxa_2">
    <visual>
      <origin rpy="0 0 0" xyz="0 0 0"/>
      <geometry>
        <mesh filename="package://robot_description/meshes/coxa_e.stl" scale="0.01 0.01 0.01"/>
      </geometry>
      <material name="">
        <color rgba="0.7 0.7 0 1"/>
      </material>
    </visual>
    <collision>
      <origin rpy="0 0 0" xyz="0 0 0"/>
      <geometry>
        <mesh filename="package://robot_description/meshes/coxa_e.stl" scale="0.01 0.01 0.01"/>
      </geometry>
      <material name="">
        <color rgba="0.7 0.7 0 1"/>
      </material>
    </collision>
    <inertial>
      <origin rpy="0.0 0.0 0.0" xyz="0.0 0.0 0.0"/>
      <!--Acho que sao os valores do centro de massa/10-->
      <mass value="0.00001"/>
      <inertia ixx="1" ixy="0" ixz="0" iyy="1" iyz="0" izz="1"/>
    </inertial>
  </link>
  <gazebo reference="coxa_2">
    <mu1>0.2</mu1>
    <mu2>0.2</mu2>
  </gazebo>
  <!--.................Joint entre coxa e femur / Link ddo
    Femur. .............-->
  <joint name="femur_centro_2" type="fixed">
    <axis xyz="0 1 0"/>
    <origin rpy=" 0 0 0" xyz="-0.52 -0.15 -0.05"/>
    <parent link="coxa_2"/>
    <child link="femur_centro_2"/>
  </joint>
  <link name="femur_centro_2">
    <inertial>
      <origin rpy="0.0 0.0 0.0" xyz="0.0 0.0 0.0"/>
      <mass value="0.00001"/>
      <inertia ixx="1" ixy="0" ixz="0" iyy="1" iyz="0" izz="1"/>
    </inertial>
  </link>
  <joint name="femur_joint_2" type="revolute">
    <origin rpy="0 0 0" xyz="0 0 0"/>
    <parent link="femur_centro_2"/>
    <child link="femur_2"/>
    <axis xyz="0 1 0"/>
    <limit effort="10000" lower="-1.57079632679" upper="1.57079632679" velocity="100"/>
  </joint>
  <transmission name="femur_transmission_2">
    <type>transmission_interface/SimpleTransmission</type>
    <joint name="femur_joint_2">
      <hardwareInterface>EffortJointInterface</hardwareInterface>
    </joint>
    <actuator name="femur_motor_2">
      <hardwareInterface>EffortJointInterface</hardwareInterface>
      <mechanicalReduction>1</mechanicalReduction>
    </actuator>
  </transmission>
  <link name="femur_2">
    <visual>
      <origin rpy="0 0 0" xyz="0 0 0"/>
      <geometry>
        <mesh filename="package://robot_description/meshes/femur.stl" scale="0.01 0.01 0.01"/>
      </geometry>
      <material name="">
        <color rgba="0 0.7 0.7 1"/>
      </material>
    </visual>
    <collision>
      <origin rpy="0 0 0" xyz="0 0 0"/>
      <geometry>
        <mesh filename="package://robot_description/meshes/femur.stl" scale="0.01 0.01 0.01"/>
      </geometry>
      <material name="">
        <color rgba="0 0.7 0.7 1"/>
      </material>
    </collision>
    <inertial>
      <origin rpy="0.0 0.0 0.0" xyz="0.0 0.0 0.0"/>
      <mass value="0.00001"/>
      <inertia ixx="1" ixy="0" ixz="0" iyy="1" iyz="0" izz="1"/>
    </inertial>
  </link>
  <gazebo reference="femur_2">
    <mu1>0.2</mu1>
    <mu2>0.2</mu2>
  </gazebo>
  <!--.................Joint entre femur e Tibia / Link do Tibia. .............-->
  <!--Joint e Link para fixar coxa (caso contrario gira em torno do centro da base)-->
  <joint name="tibia_centro_2" type="fixed">
    <axis xyz="0 1 0"/>
    <origin rpy="0 0 0" xyz="0 0.045 -0.36"/>
    <parent link="femur_2"/>
    <child link="tibia_centro_2"/>
  </joint>
  <link name="tibia_centro_2">
    <inertial>
      <origin rpy="0.0 0.0 0.0" xyz="0.0 0.0 0.0"/>
      <mass value="0.00001"/>
      <inertia ixx="1" ixy="0" ixz="0" iyy="1" iyz="0" izz="1"/>
    </inertial>
  </link>
  <joint name="tibia_joint_2" type="revolute">
    <origin rpy="0 0 0" xyz="0 0 0"/>
    <parent link="tibia_centro_2"/>
    <child link="tibia_2"/>
    <axis xyz="0 1 0"/>
    <limit effort="10000" lower="-1.57079632679" upper="1.57079632679" velocity="100"/>
  </joint>
  <transmission name="tibia_transmission_2">
    <type>transmission_interface/SimpleTransmission</type>
    <joint name="tibia_joint_2">
      <hardwareInterface>EffortJointInterface</hardwareInterface>
    </joint>
    <actuator name="tibia_motor_2">
      <hardwareInterface>EffortJointInterface</hardwareInterface>
      <mechanicalReduction>1</mechanicalReduction>
    </actuator>
  </transmission>
  <link name="tibia_2">
    <visual>
      <origin rpy="0 0 0 " xyz="-0 0 0"/>
      <geometry>
        <mesh filename="package://robot_description/meshes/tibia.stl" scale="0.01 0.01 0.01"/>
      </geometry>
      <material name="">
        <color rgba="0.7 0 0.7 1"/>
      </material>
    </visual>
    <collision>
      <origin rpy="0 0 0 " xyz="0.0 0.0 0"/>
      <geometry>
        <mesh filename="package://robot_description/meshes/tibia.stl" scale="0.01 0.01 0.01"/>
      </geometry>
      <material name="">
        <color rgba="0 0.7 0.7 1"/>
      </material>
    </collision>
    <inertial>
      <origin rpy="0.0 0.0 0.0" xyz="0.0 0.0 0.0"/>
      <mass value="0.00001"/>
      <inertia ixx="1" ixy="0" ixz="0" iyy="1" iyz="0" izz="1"/>
    </inertial>
  </link>
  

!--............................. Patas......................................--&gt;

  <joint name="tibia_foot_joint_2" type="fixed">
    <axis xyz="0 0 1"/>
    <origin rpy="0 0 0" xyz="0 0.08 -0.57"/>
    <parent link="tibia_2"/>
    <child link="tibia_foot_2"/>
  </joint>
  <link name="tibia_foot_2">
</link>
  <!--Joint e Link para fixar coxa (caso contrario gira em torno do centro da base)-->
  <joint name="perna_centro_joint_3" type="fixed">
    <axis xyz="0 0 1"/>
    <origin rpy="0 0 0" xyz="-0.115 -0.65 0.91"/>
    <!-- imp -->
    <parent link="thorax"/>
    <child link="perna_centro_3"/>
  </joint>
  <link name="perna_centro_3">
    <inertial>
      <origin rpy="0.0 0.0 0.0" xyz="0.0 0.0 0.0"/>
      <mass value="0.00001"/>
      <inertia ixx="1" ixy="0" ixz="0" iyy="1" iyz="0" izz="1"/>
    </inertial>
  </link>
  <!--..............Joint entre "thorax"(thorax) e coxa / Link da Coxa ..........-->
  <joint name="coxa_joint_3" type="revolute">
    <parent link="perna_centro_3"/>
    <axis xyz="0 0 1"/>
    <origin rpy="0 0 0" xyz="0 0 0"/>
    <!-- segundo-->
    <child link="coxa_3"/>
    <limit effort="10000" lower="-1.57079632679" upper="1.57079632679" velocity="100"/>
  </joint>
  <transmission name="coxa_transmission_3">
    <type>transmission_interface/SimpleTransmission</type>
    <joint name="coxa_joint_3">
      <hardwareInterface>EffortJointInterface</hardwareInterface>
    </joint>
    <actuator name="coxa_motor_3">
      <hardwareInterface>EffortJointInterface</hardwareInterface>
      <mechanicalReduction>1</mechanicalReduction>
    </actuator>
  </transmission>
  <link name="coxa_3">
    <visual>
      <origin rpy="0 0 0" xyz="0 0 0"/>
      <geometry>
        <mesh filename="package://robot_description/meshes/coxa_e.stl" scale="0.01 0.01 0.01"/>
      </geometry>
      <material name="">
        <color rgba="0.7 0.7 0 1"/>
      </material>
    </visual>
    <collision>
      <origin rpy="0 0 0" xyz="0 0 0"/>
      <geometry>
        <mesh filename="package://robot_description/meshes/coxa_e.stl" scale="0.01 0.01 0.01"/>
      </geometry>
      <material name="">
        <color rgba="0.7 0.7 0 1"/>
      </material>
    </collision>
    <inertial>
      <origin rpy="0.0 0.0 0.0" xyz="0.0 0.0 0.0"/>
      <!--Acho que sao os valores do centro de massa/10-->
      <mass value="0.00001"/>
      <inertia ixx="1" ixy="0" ixz="0" iyy="1" iyz="0" izz="1"/>
    </inertial>
  </link>
  <gazebo reference="coxa_3">
    <mu1>0.2</mu1>
    <mu2>0.2</mu2>
  </gazebo>
  <!--.................Joint entre coxa e femur / Link ddo
    Femur. .............-->
  <joint name="femur_centro_3" type="fixed">
    <axis xyz="0 1 0"/>
    <origin rpy=" 0 0 0" xyz="-0.52 -0.15 -0.05"/>
    <parent link="coxa_3"/>
    <child link="femur_centro_3"/>
  </joint>
  <link name="femur_centro_3">
    <inertial>
      <origin rpy="0.0 0.0 0.0" xyz="0.0 0.0 0.0"/>
      <mass value="0.00001"/>
      <inertia ixx="1" ixy="0" ixz="0" iyy="1" iyz="0" izz="1"/>
    </inertial>
  </link>
  <joint name="femur_joint_3" type="revolute">
    <origin rpy="0 0 0" xyz="0 0 0"/>
    <parent link="femur_centro_3"/>
    <child link="femur_3"/>
    <axis xyz="0 1 0"/>
    <limit effort="10000" lower="-1.57079632679" upper="1.57079632679" velocity="100"/>
  </joint>
  <transmission name="femur_transmission_3">
    <type>transmission_interface/SimpleTransmission</type>
    <joint name="femur_joint_3">
      <hardwareInterface>EffortJointInterface</hardwareInterface>
    </joint>
    <actuator name="femur_motor_3">
      <hardwareInterface>EffortJointInterface</hardwareInterface>
      <mechanicalReduction>1</mechanicalReduction>
    </actuator>
  </transmission>
  <link name="femur_3">
    <visual>
      <origin rpy="0 0 0" xyz="0 0 0"/>
      <geometry>
        <mesh filename="package://robot_description/meshes/femur.stl" scale="0.01 0.01 0.01"/>
      </geometry>
      <material name="">
        <color rgba="0 0.7 0.7 1"/>
      </material>
    </visual>
    <collision>
      <origin rpy="0 0 0" xyz="0 0 0"/>
      <geometry>
        <mesh filename="package://robot_description/meshes/femur.stl" scale="0.01 0.01 0.01"/>
      </geometry>
      <material name="">
        <color rgba="0 0.7 0.7 1"/>
      </material>
    </collision>
    <inertial>
      <origin rpy="0.0 0.0 0.0" xyz="0.0 0.0 0.0"/>
      <mass value="0.00001"/>
      <inertia ixx="1" ixy="0" ixz="0" iyy="1" iyz="0" izz="1"/>
    </inertial>
  </link>
  <gazebo reference="femur_3">
    <mu1>0.2</mu1>
    <mu2>0.2</mu2>
  </gazebo>
  <!--.................Joint entre femur e Tibia / Link do Tibia. .............-->
  <!--Joint e Link para fixar coxa (caso contrario gira em torno do centro da base)-->
  <joint name="tibia_centro_3" type="fixed">
    <axis xyz="0 1 0"/>
    <origin rpy="0 0 0" xyz="0 0.045 -0.36"/>
    <parent link="femur_3"/>
    <child link="tibia_centro_3"/>
  </joint>
  <link name="tibia_centro_3">
    <inertial>
      <origin rpy="0.0 0.0 0.0" xyz="0.0 0.0 0.0"/>
      <mass value="0.00001"/>
      <inertia ixx="1" ixy="0" ixz="0" iyy="1" iyz="0" izz="1"/>
    </inertial>
  </link>
  <joint name="tibia_joint_3" type="revolute">
    <origin rpy="0 0 0" xyz="0 0 0"/>
    <parent link="tibia_centro_3"/>
    <child link="tibia_3"/>
    <axis xyz="0 1 0"/>
    <limit effort="10000" lower="-1.57079632679" upper="1.57079632679" velocity="100"/>
  </joint>
  <transmission name="tibia_transmission_3">
    <type>transmission_interface/SimpleTransmission</type>
    <joint name="tibia_joint_3">
      <hardwareInterface>EffortJointInterface</hardwareInterface>
    </joint>
    <actuator name="tibia_motor_3">
      <hardwareInterface>EffortJointInterface</hardwareInterface>
      <mechanicalReduction>1</mechanicalReduction>
    </actuator>
  </transmission>
  <link name="tibia_3">
    <visual>
      <origin rpy="0 0 0 " xyz="-0 0 0"/>
      <geometry>
        <mesh filename="package://robot_description/meshes/tibia.stl" scale="0.01 0.01 0.01"/>
      </geometry>
      <material name="">
        <color rgba="0.7 0 0.7 1"/>
      </material>
    </visual>
    <collision>
      <origin rpy="0 0 0 " xyz="0.0 0.0 0"/>
      <geometry>
        <mesh filename="package://robot_description/meshes/tibia.stl" scale="0.01 0.01 0.01"/>
      </geometry>
      <material name="">
        <color rgba="0 0.7 0.7 1"/>
      </material>
    </collision>
    <inertial>
      <origin rpy="0.0 0.0 0.0" xyz="0.0 0.0 0.0"/>
      <mass value="0.00001"/>
      <inertia ixx="1" ixy="0" ixz="0" iyy="1" iyz="0" izz="1"/>
    </inertial>
  </link>
  

!--............................. Patas......................................--&gt;

  <joint name="tibia_foot_joint_3" type="fixed">
    <axis xyz="0 0 1"/>
    <origin rpy="0 0 0" xyz="0 0.08 -0.57"/>
    <parent link="tibia_3"/>
    <child link="tibia_foot_3"/>
  </joint>
  <link name="tibia_foot_3">
</link>
  <!--Joint e Link para fixar coxa (caso contrario gira em torno do centro da base)-->
  <joint name="perna_centro_joint_4" type="fixed">
    <axis xyz="0 0 1"/>
    <origin rpy="0 0 0" xyz="0.115 0.65 0.91"/>
    <!-- imp -->
    <parent link="thorax"/>
    <child link="perna_centro_4"/>
  </joint>
  <link name="perna_centro_4">
    <inertial>
      <origin rpy="0.0 0.0 0.0" xyz="0.0 0.0 0.0"/>
      <mass value="0.00001"/>
      <inertia ixx="1" ixy="0" ixz="0" iyy="1" iyz="0" izz="1"/>
    </inertial>
  </link>
  <!--..............Joint entre "thorax"(thorax) e coxa / Link da Coxa ..........-->
  <joint name="coxa_joint_4" type="revolute">
    <parent link="perna_centro_4"/>
    <axis xyz="0 0 1"/>
    <origin rpy="0 0 0" xyz="0 0 0"/>
    <!-- segundo-->
    <child link="coxa_4"/>
    <limit effort="10000" lower="-1.57079632679" upper="1.57079632679" velocity="100"/>
  </joint>
  <transmission name="coxa_transmission_4">
    <type>transmission_interface/SimpleTransmission</type>
    <joint name="coxa_joint_4">
      <hardwareInterface>EffortJointInterface</hardwareInterface>
    </joint>
    <actuator name="coxa_motor_4">
      <hardwareInterface>EffortJointInterface</hardwareInterface>
      <mechanicalReduction>1</mechanicalReduction>
    </actuator>
  </transmission>
  <link name="coxa_4">
    <visual>
      <origin rpy="0 0 0" xyz="0 0 0"/>
      <geometry>
        <mesh filename="package://robot_description/meshes/coxa_d.stl" scale="0.01 0.01 0.01"/>
      </geometry>
      <material name="">
        <color rgba="0.7 0.7 0 1"/>
      </material>
    </visual>
    <collision>
      <origin rpy="0 0 0" xyz="0 0 0"/>
      <geometry>
        <mesh filename="package://robot_description/meshes/coxa_d.stl" scale="0.01 0.01 0.01"/>
      </geometry>
      <material name="">
        <color rgba="0.7 0.7 0 1"/>
      </material>
    </collision>
    <inertial>
      <origin rpy="0.0 0.0 0.0" xyz="0.0 0.0 0.0"/>
      <!--Acho que sao os valores do centro de massa/10-->
      <mass value="0.00001"/>
      <inertia ixx="1" ixy="0" ixz="0" iyy="1" iyz="0" izz="1"/>
    </inertial>
  </link>
  <gazebo reference="coxa_4">
    <mu1>0.2</mu1>
    <mu2>0.2</mu2>
  </gazebo>
  <!--.................Joint entre coxa e femur / Link ddo
    Femur. .............-->
  <joint name="femur_centro_4" type="fixed">
    <axis xyz="0 1 0"/>
    <origin rpy=" 0 0 0" xyz="0.52 -0.15 -0.05"/>
    <parent link="coxa_4"/>
    <child link="femur_centro_4"/>
  </joint>
  <link name="femur_centro_4">
    <inertial>
      <origin rpy="0.0 0.0 0.0" xyz="0.0 0.0 0.0"/>
      <mass value="0.00001"/>
      <inertia ixx="1" ixy="0" ixz="0" iyy="1" iyz="0" izz="1"/>
    </inertial>
  </link>
  <joint name="femur_joint_4" type="revolute">
    <origin rpy="0 0 0" xyz="0 0 0"/>
    <parent link="femur_centro_4"/>
    <child link="femur_4"/>
    <axis xyz="0 1 0"/>
    <limit effort="10000" lower="-1.57079632679" upper="1.57079632679" velocity="100"/>
  </joint>
  <transmission name="femur_transmission_4">
    <type>transmission_interface/SimpleTransmission</type>
    <joint name="femur_joint_4">
      <hardwareInterface>EffortJointInterface</hardwareInterface>
    </joint>
    <actuator name="femur_motor_4">
      <hardwareInterface>EffortJointInterface</hardwareInterface>
      <mechanicalReduction>1</mechanicalReduction>
    </actuator>
  </transmission>
  <link name="femur_4">
    <visual>
      <origin rpy="0 0 0" xyz="0 0 0"/>
      <geometry>
        <mesh filename="package://robot_description/meshes/femur.stl" scale="0.01 0.01 0.01"/>
      </geometry>
      <material name="">
        <color rgba="0 0.7 0.7 1"/>
      </material>
    </visual>
    <collision>
      <origin rpy="0 0 0" xyz="0 0 0"/>
      <geometry>
        <mesh filename="package://robot_description/meshes/femur.stl" scale="0.01 0.01 0.01"/>
      </geometry>
      <material name="">
        <color rgba="0 0.7 0.7 1"/>
      </material>
    </collision>
    <inertial>
      <origin rpy="0.0 0.0 0.0" xyz="0.0 0.0 0.0"/>
      <mass value="0.00001"/>
      <inertia ixx="1" ixy="0" ixz="0" iyy="1" iyz="0" izz="1"/>
    </inertial>
  </link>
  <gazebo reference="femur_4">
    <mu1>0.2</mu1>
    <mu2>0.2</mu2>
  </gazebo>
  <!--.................Joint entre femur e Tibia / Link do Tibia. .............-->
  <!--Joint e Link para fixar coxa (caso contrario gira em torno do centro da base)-->
  <joint name="tibia_centro_4" type="fixed">
    <axis xyz="0 1 0"/>
    <origin rpy="0 0 0" xyz="0 0.045 -0.36"/>
    <parent link="femur_4"/>
    <child link="tibia_centro_4"/>
  </joint>
  <link name="tibia_centro_4">
    <inertial>
      <origin rpy="0.0 0.0 0.0" xyz="0.0 0.0 0.0"/>
      <mass value="0.00001"/>
      <inertia ixx="1" ixy="0" ixz="0" iyy="1" iyz="0" izz="1"/>
    </inertial>
  </link>
  <joint name="tibia_joint_4" type="revolute">
    <origin rpy="0 0 0" xyz="0 0 0"/>
    <parent link="tibia_centro_4"/>
    <child link="tibia_4"/>
    <axis xyz="0 1 0"/>
    <limit effort="10000" lower="-1.57079632679" upper="1.57079632679" velocity="100"/>
  </joint>
  <transmission name="tibia_transmission_4">
    <type>transmission_interface/SimpleTransmission</type>
    <joint name="tibia_joint_4">
      <hardwareInterface>EffortJointInterface</hardwareInterface>
    </joint>
    <actuator name="tibia_motor_4">
      <hardwareInterface>EffortJointInterface</hardwareInterface>
      <mechanicalReduction>1</mechanicalReduction>
    </actuator>
  </transmission>
  <link name="tibia_4">
    <visual>
      <origin rpy="0 0 0 " xyz="-0 0 0"/>
      <geometry>
        <mesh filename="package://robot_description/meshes/tibia.stl" scale="0.01 0.01 0.01"/>
      </geometry>
      <material name="">
        <color rgba="0.7 0 0.7 1"/>
      </material>
    </visual>
    <collision>
      <origin rpy="0 0 0 " xyz="0.0 0.0 0"/>
      <geometry>
        <mesh filename="package://robot_description/meshes/tibia.stl" scale="0.01 0.01 0.01"/>
      </geometry>
      <material name="">
        <color rgba="0 0.7 0.7 1"/>
      </material>
    </collision>
    <inertial>
      <origin rpy="0.0 0.0 0.0" xyz="0.0 0.0 0.0"/>
      <mass value="0.00001"/>
      <inertia ixx="1" ixy="0" ixz="0" iyy="1" iyz="0" izz="1"/>
    </inertial>
  </link>
  

!--............................. Patas......................................--&gt;

  <joint name="tibia_foot_joint_4" type="fixed">
    <axis xyz="0 0 1"/>
    <origin rpy="0 0 0" xyz="0 0.08 -0.57"/>
    <parent link="tibia_4"/>
    <child link="tibia_foot_4"/>
  </joint>
  <link name="tibia_foot_4">
</link>
  <!--Joint e Link para fixar coxa (caso contrario gira em torno do centro da base)-->
  <joint name="perna_centro_joint_5" type="fixed">
    <axis xyz="0 0 1"/>
    <origin rpy="0 0 0" xyz="0.115 0 0.91"/>
    <!-- imp -->
    <parent link="thorax"/>
    <child link="perna_centro_5"/>
  </joint>
  <link name="perna_centro_5">
    <inertial>
      <origin rpy="0.0 0.0 0.0" xyz="0.0 0.0 0.0"/>
      <mass value="0.00001"/>
      <inertia ixx="1" ixy="0" ixz="0" iyy="1" iyz="0" izz="1"/>
    </inertial>
  </link>
  <!--..............Joint entre "thorax"(thorax) e coxa / Link da Coxa ..........-->
  <joint name="coxa_joint_5" type="revolute">
    <parent link="perna_centro_5"/>
    <axis xyz="0 0 1"/>
    <origin rpy="0 0 0" xyz="0 0 0"/>
    <!-- segundo-->
    <child link="coxa_5"/>
    <limit effort="10000" lower="-1.57079632679" upper="1.57079632679" velocity="100"/>
  </joint>
  <transmission name="coxa_transmission_5">
    <type>transmission_interface/SimpleTransmission</type>
    <joint name="coxa_joint_5">
      <hardwareInterface>EffortJointInterface</hardwareInterface>
    </joint>
    <actuator name="coxa_motor_5">
      <hardwareInterface>EffortJointInterface</hardwareInterface>
      <mechanicalReduction>1</mechanicalReduction>
    </actuator>
  </transmission>
  <link name="coxa_5">
    <visual>
      <origin rpy="0 0 0" xyz="0 0 0"/>
      <geometry>
        <mesh filename="package://robot_description/meshes/coxa_d.stl" scale="0.01 0.01 0.01"/>
      </geometry>
      <material name="">
        <color rgba="0.7 0.7 0 1"/>
      </material>
    </visual>
    <collision>
      <origin rpy="0 0 0" xyz="0 0 0"/>
      <geometry>
        <mesh filename="package://robot_description/meshes/coxa_d.stl" scale="0.01 0.01 0.01"/>
      </geometry>
      <material name="">
        <color rgba="0.7 0.7 0 1"/>
      </material>
    </collision>
    <inertial>
      <origin rpy="0.0 0.0 0.0" xyz="0.0 0.0 0.0"/>
      <!--Acho que sao os valores do centro de massa/10-->
      <mass value="0.00001"/>
      <inertia ixx="1" ixy="0" ixz="0" iyy="1" iyz="0" izz="1"/>
    </inertial>
  </link>
  <gazebo reference="coxa_5">
    <mu1>0.2</mu1>
    <mu2>0.2</mu2>
  </gazebo>
  <!--.................Joint entre coxa e femur / Link ddo
    Femur. .............-->
  <joint name="femur_centro_5" type="fixed">
    <axis xyz="0 1 0"/>
    <origin rpy=" 0 0 0" xyz="0.52 -0.15 -0.05"/>
    <parent link="coxa_5"/>
    <child link="femur_centro_5"/>
  </joint>
  <link name="femur_centro_5">
    <inertial>
      <origin rpy="0.0 0.0 0.0" xyz="0.0 0.0 0.0"/>
      <mass value="0.00001"/>
      <inertia ixx="1" ixy="0" ixz="0" iyy="1" iyz="0" izz="1"/>
    </inertial>
  </link>
  <joint name="femur_joint_5" type="revolute">
    <origin rpy="0 0 0" xyz="0 0 0"/>
    <parent link="femur_centro_5"/>
    <child link="femur_5"/>
    <axis xyz="0 1 0"/>
    <limit effort="10000" lower="-1.57079632679" upper="1.57079632679" velocity="100"/>
  </joint>
  <transmission name="femur_transmission_5">
    <type>transmission_interface/SimpleTransmission</type>
    <joint name="femur_joint_5">
      <hardwareInterface>EffortJointInterface</hardwareInterface>
    </joint>
    <actuator name="femur_motor_5">
      <hardwareInterface>EffortJointInterface</hardwareInterface>
      <mechanicalReduction>1</mechanicalReduction>
    </actuator>
  </transmission>
  <link name="femur_5">
    <visual>
      <origin rpy="0 0 0" xyz="0 0 0"/>
      <geometry>
        <mesh filename="package://robot_description/meshes/femur.stl" scale="0.01 0.01 0.01"/>
      </geometry>
      <material name="">
        <color rgba="0 0.7 0.7 1"/>
      </material>
    </visual>
    <collision>
      <origin rpy="0 0 0" xyz="0 0 0"/>
      <geometry>
        <mesh filename="package://robot_description/meshes/femur.stl" scale="0.01 0.01 0.01"/>
      </geometry>
      <material name="">
        <color rgba="0 0.7 0.7 1"/>
      </material>
    </collision>
    <inertial>
      <origin rpy="0.0 0.0 0.0" xyz="0.0 0.0 0.0"/>
      <mass value="0.00001"/>
      <inertia ixx="1" ixy="0" ixz="0" iyy="1" iyz="0" izz="1"/>
    </inertial>
  </link>
  <gazebo reference="femur_5">
    <mu1>0.2</mu1>
    <mu2>0.2</mu2>
  </gazebo>
  <!--.................Joint entre femur e Tibia / Link do Tibia. .............-->
  <!--Joint e Link para fixar coxa (caso contrario gira em torno do centro da base)-->
  <joint name="tibia_centro_5" type="fixed">
    <axis xyz="0 1 0"/>
    <origin rpy="0 0 0" xyz="0 0.045 -0.36"/>
    <parent link="femur_5"/>
    <child link="tibia_centro_5"/>
  </joint>
  <link name="tibia_centro_5">
    <inertial>
      <origin rpy="0.0 0.0 0.0" xyz="0.0 0.0 0.0"/>
      <mass value="0.00001"/>
      <inertia ixx="1" ixy="0" ixz="0" iyy="1" iyz="0" izz="1"/>
    </inertial>
  </link>
  <joint name="tibia_joint_5" type="revolute">
    <origin rpy="0 0 0" xyz="0 0 0"/>
    <parent link="tibia_centro_5"/>
    <child link="tibia_5"/>
    <axis xyz="0 1 0"/>
    <limit effort="10000" lower="-1.57079632679" upper="1.57079632679" velocity="100"/>
  </joint>
  <transmission name="tibia_transmission_5">
    <type>transmission_interface/SimpleTransmission</type>
    <joint name="tibia_joint_5">
      <hardwareInterface>EffortJointInterface</hardwareInterface>
    </joint>
    <actuator name="tibia_motor_5">
      <hardwareInterface>EffortJointInterface</hardwareInterface>
      <mechanicalReduction>1</mechanicalReduction>
    </actuator>
  </transmission>
  <link name="tibia_5">
    <visual>
      <origin rpy="0 0 0 " xyz="-0 0 0"/>
      <geometry>
        <mesh filename="package://robot_description/meshes/tibia.stl" scale="0.01 0.01 0.01"/>
      </geometry>
      <material name="">
        <color rgba="0.7 0 0.7 1"/>
      </material>
    </visual>
    <collision>
      <origin rpy="0 0 0 " xyz="0.0 0.0 0"/>
      <geometry>
        <mesh filename="package://robot_description/meshes/tibia.stl" scale="0.01 0.01 0.01"/>
      </geometry>
      <material name="">
        <color rgba="0 0.7 0.7 1"/>
      </material>
    </collision>
    <inertial>
      <origin rpy="0.0 0.0 0.0" xyz="0.0 0.0 0.0"/>
      <mass value="0.00001"/>
      <inertia ixx="1" ixy="0" ixz="0" iyy="1" iyz="0" izz="1"/>
    </inertial>
  </link>
  

!--............................. Patas......................................--&gt;

  <joint name="tibia_foot_joint_5" type="fixed">
    <axis xyz="0 0 1"/>
    <origin rpy="0 0 0" xyz="0 0.08 -0.57"/>
    <parent link="tibia_5"/>
    <child link="tibia_foot_5"/>
  </joint>
  <link name="tibia_foot_5">
</link>
  <!--Joint e Link para fixar coxa (caso contrario gira em torno do centro da base)-->
  <joint name="perna_centro_joint_6" type="fixed">
    <axis xyz="0 0 1"/>
    <origin rpy="0 0 0" xyz="0.115 -0.65 0.91"/>
    <!-- imp -->
    <parent link="thorax"/>
    <child link="perna_centro_6"/>
  </joint>
  <link name="perna_centro_6">
    <inertial>
      <origin rpy="0.0 0.0 0.0" xyz="0.0 0.0 0.0"/>
      <mass value="0.00001"/>
      <inertia ixx="1" ixy="0" ixz="0" iyy="1" iyz="0" izz="1"/>
    </inertial>
  </link>
  <!--..............Joint entre "thorax"(thorax) e coxa / Link da Coxa ..........-->
  <joint name="coxa_joint_6" type="revolute">
    <parent link="perna_centro_6"/>
    <axis xyz="0 0 1"/>
    <origin rpy="0 0 0" xyz="0 0 0"/>
    <!-- segundo-->
    <child link="coxa_6"/>
    <limit effort="10000" lower="-1.57079632679" upper="1.57079632679" velocity="100"/>
  </joint>
  <transmission name="coxa_transmission_6">
    <type>transmission_interface/SimpleTransmission</type>
    <joint name="coxa_joint_6">
      <hardwareInterface>EffortJointInterface</hardwareInterface>
    </joint>
    <actuator name="coxa_motor_6">
      <hardwareInterface>EffortJointInterface</hardwareInterface>
      <mechanicalReduction>1</mechanicalReduction>
    </actuator>
  </transmission>
  <link name="coxa_6">
    <visual>
      <origin rpy="0 0 0" xyz="0 0 0"/>
      <geometry>
        <mesh filename="package://robot_description/meshes/coxa_d.stl" scale="0.01 0.01 0.01"/>
      </geometry>
      <material name="">
        <color rgba="0.7 0.7 0 1"/>
      </material>
    </visual>
    <collision>
      <origin rpy="0 0 0" xyz="0 0 0"/>
      <geometry>
        <mesh filename="package://robot_description/meshes/coxa_d.stl" scale="0.01 0.01 0.01"/>
      </geometry>
      <material name="">
        <color rgba="0.7 0.7 0 1"/>
      </material>
    </collision>
    <inertial>
      <origin rpy="0.0 0.0 0.0" xyz="0.0 0.0 0.0"/>
      <!--Acho que sao os valores do centro de massa/10-->
      <mass value="0.00001"/>
      <inertia ixx="1" ixy="0" ixz="0" iyy="1" iyz="0" izz="1"/>
    </inertial>
  </link>
  <gazebo reference="coxa_6">
    <mu1>0.2</mu1>
    <mu2>0.2</mu2>
  </gazebo>
  <!--.................Joint entre coxa e femur / Link ddo
    Femur. .............-->
  <joint name="femur_centro_6" type="fixed">
    <axis xyz="0 1 0"/>
    <origin rpy=" 0 0 0" xyz="0.52 -0.15 -0.05"/>
    <parent link="coxa_6"/>
    <child link="femur_centro_6"/>
  </joint>
  <link name="femur_centro_6">
    <inertial>
      <origin rpy="0.0 0.0 0.0" xyz="0.0 0.0 0.0"/>
      <mass value="0.00001"/>
      <inertia ixx="1" ixy="0" ixz="0" iyy="1" iyz="0" izz="1"/>
    </inertial>
  </link>
  <joint name="femur_joint_6" type="revolute">
    <origin rpy="0 0 0" xyz="0 0 0"/>
    <parent link="femur_centro_6"/>
    <child link="femur_6"/>
    <axis xyz="0 1 0"/>
    <limit effort="10000" lower="-1.57079632679" upper="1.57079632679" velocity="100"/>
  </joint>
  <transmission name="femur_transmission_6">
    <type>transmission_interface/SimpleTransmission</type>
    <joint name="femur_joint_6">
      <hardwareInterface>EffortJointInterface</hardwareInterface>
    </joint>
    <actuator name="femur_motor_6">
      <hardwareInterface>EffortJointInterface</hardwareInterface>
      <mechanicalReduction>1</mechanicalReduction>
    </actuator>
  </transmission>
  <link name="femur_6">
    <visual>
      <origin rpy="0 0 0" xyz="0 0 0"/>
      <geometry>
        <mesh filename="package://robot_description/meshes/femur.stl" scale="0.01 0.01 0.01"/>
      </geometry>
      <material name="">
        <color rgba="0 0.7 0.7 1"/>
      </material>
    </visual>
    <collision>
      <origin rpy="0 0 0" xyz="0 0 0"/>
      <geometry>
        <mesh filename="package://robot_description/meshes/femur.stl" scale="0.01 0.01 0.01"/>
      </geometry>
      <material name="">
        <color rgba="0 0.7 0.7 1"/>
      </material>
    </collision>
    <inertial>
      <origin rpy="0.0 0.0 0.0" xyz="0.0 0.0 0.0"/>
      <mass value="0.00001"/>
      <inertia ixx="1" ixy="0" ixz="0" iyy="1" iyz="0" izz="1"/>
    </inertial>
  </link>
  <gazebo reference="femur_6">
    <mu1>0.2</mu1>
    <mu2>0.2</mu2>
  </gazebo>
  <!--.................Joint entre femur e Tibia / Link do Tibia. .............-->
  <!--Joint e Link para fixar coxa (caso contrario gira em torno do centro da base)-->
  <joint name="tibia_centro_6" type="fixed">
    <axis xyz="0 1 0"/>
    <origin rpy="0 0 0" xyz="0 0.045 -0.36"/>
    <parent link="femur_6"/>
    <child link="tibia_centro_6"/>
  </joint>
  <link name="tibia_centro_6">
    <inertial>
      <origin rpy="0.0 0.0 0.0" xyz="0.0 0.0 0.0"/>
      <mass value="0.00001"/>
      <inertia ixx="1" ixy="0" ixz="0" iyy="1" iyz="0" izz="1"/>
    </inertial>
  </link>
  <joint name="tibia_joint_6" type="revolute">
    <origin rpy="0 0 0" xyz="0 0 0"/>
    <parent link="tibia_centro_6"/>
    <child link="tibia_6"/>
    <axis xyz="0 1 0"/>
    <limit effort="10000" lower="-1.57079632679" upper="1.57079632679" velocity="100"/>
  </joint>
  <transmission name="tibia_transmission_6">
    <type>transmission_interface/SimpleTransmission</type>
    <joint name="tibia_joint_6">
      <hardwareInterface>EffortJointInterface</hardwareInterface>
    </joint>
    <actuator name="tibia_motor_6">
      <hardwareInterface>EffortJointInterface</hardwareInterface>
      <mechanicalReduction>1</mechanicalReduction>
    </actuator>
  </transmission>
  <link name="tibia_6">
    <visual>
      <origin rpy="0 0 0 " xyz="-0 0 0"/>
      <geometry>
        <mesh filename="package://robot_description/meshes/tibia.stl" scale="0.01 0.01 0.01"/>
      </geometry>
      <material name="">
        <color rgba="0.7 0 0.7 1"/>
      </material>
    </visual>
    <collision>
      <origin rpy="0 0 0 " xyz="0.0 0.0 0"/>
      <geometry>
        <mesh filename="package://robot_description/meshes/tibia.stl" scale="0.01 0.01 0.01"/>
      </geometry>
      <material name="">
        <color rgba="0 0.7 0.7 1"/>
      </material>
    </collision>
    <inertial>
      <origin rpy="0.0 0.0 0.0" xyz="0.0 0.0 0.0"/>
      <mass value="0.00001"/>
      <inertia ixx="1" ixy="0" ixz="0" iyy="1" iyz="0" izz="1"/>
    </inertial>
  </link>
  

!--............................. Patas......................................--&gt;

  <joint name="tibia_foot_joint_6" type="fixed">
    <axis xyz="0 0 1"/>
    <origin rpy="0 0 0" xyz="0 0.08 -0.57"/>
    <parent link="tibia_6"/>
    <child link="tibia_foot_6"/>
  </joint>
  <link name="tibia_foot_6">
</link>
</robot>
